Workbook
Name _Toc190024795: 'ESPAÑOL '!$N$8
Name _Toc190024795: MATEMATICA!$N$8

Sheet LISTA DE ESTUDIANTES
B1: Estudiante | C1: Sección | D1: Cédula | E1: Observaciones/ FUNCIONAMIENTO
A2: 1 | B2: Agüero Brénes Freyser | C2: 7-1 | E2: Revisar Expediente
A3: 2 | B3: Guillen Chávez Omar Rafael | C3: 7-1 | E3: Revisar Expediente
A4: 3 | B4: Guillen Guido Eneizer | C4: 7-1 | E4: Revisar Expediente
A5: 4 | B5: Morales Arosemena Keilor Joshua | C5: 7-1 | E5: Revisar Expediente Cambio de apellidos Arosemena Siles
A6: 5 | B6: González Martínez Josué | C6: 7-1 | E6: Revisar Expediente
A7: 6 | B7: Briones Sánchez Yeisliany | C7: 7-2 | E7: Revisar Expediente
A8: 7 | B8: Cerdas Guerrero Rihanna | C8: 7-2 | E8: Revisar Expediente
A9: 8 | B9: Cortes Espinoza Sara Ibeth | C9: 7-2 | E9: Revisar Expediente
A10: 9 | B10: Franco Caballero Bayron | C10: 7–2 | E10: Según nota de matrícula que señala adecuación. Falta Revisar expediente
A11: 10 | B11: Martínez Artola Julisa | C11: 7-2 | E11: Revisar Expediente
A12: 11 | B12: Palacios Montezuma Kenya | C12: 7-2 | E12: Revisar Expediente
A13: 12 | B13: Ávila Ramírez Alejandra Victoria | C13: 8-1 | E13: Revisar Expediente
... A64: 63 | B64: González Corrales Laura | C64: 11-5 | E64: Español y la Ciencias.
A65: 64
A66: 65
A67: 66
A68: 67
A69: 68
A70: 69
A71: 70
A72: 71
A73: 72
A74: 73
A75: 74
A76: 75
... A102: 101

Sheet ESPAÑOL 
N1: ÁREA DE TRABAJO PARA EL INFORME
B3: GUÍA DE LOS CÓDIGOS
U4: =IFERROR(INDEX('LISTA DE ESTUDIANTES'!$C$2:$C$102, MATCH($N$10,'LISTA DE ESTUDIANTES'!B2:B102, 0)), " ") -> 8-1
B5: Apoyos sugeridos que podría brindar el docente regular. | C5: VIDEO DE USO:
A6: A.P.1 | B6: Utilizar su cercanía física para mantenerlo atento a la clase. | S6: CTRL + P, PARA IMPRIMIR O TAMBIÉN LO PUEDE GUARDAR COMO PDF
A7: A.P.2 | B7: Utilizar la tutoría entre compañeros. | M7: ANEXO 2: REGISTRO DE APOYOS EDUCATIVOS
A8: A.P.3 | B8: Brindar acercamiento físico y las manifestaciones de apoyo. | N8: Curso lectivo 2025
A9: A.P.4 | B9: Reforzar cada logro por más pequeño que este sea. | C9: https://youtu.be/wF6TR_aaiRc | K9: Institución: Colegio Nocturno La Cuesta | P9: Circuito: 06
A10: A.P.5 | B10: Reforzar la autoestima mediante actividades que le permitan éxito, particularizando en características cognitivas y sociales. | K10: Nombre del estudiante: | N10: Caballero González Angie Guiselle | P10: =+ "Sección: " &$U$4 -> Sección: 8-1 | S10: ESCOJA UN ESTUDIANTE EN LA LISTA Y SE DEPLEGA TODA LA INFORMACIÓN RELACIONADA
A11: A.P.6 | B11: Utilizar constantemente la estrategia de trabajo cooperativo con la finalidad de que logre beneficiar y beneficiarse de las experiencias de otros compañeros y así reforzar su seguridad en la ejecución de los aprendizajes. | K11: Nivel de Funcionamiento: | N11: =IFERROR(INDEX('LISTA DE ESTUDIANTES'!$E$2:$E$102,MATCH($N$10,'LISTA DE ESTUDIANTES'!$B$2:$B$102, 0)), " ") -> Revisar Expediente | P11: =+TODAY() -> 46158
A12: A.P.7 | B12: Dar responsabilidades especificas al estudiante dentro del aula y hogar para reforzar su autoconfianza generando responsabilidad e independencia. | K12: Docente responsable: | N12: Gerardo Ramirez Rojas | O12: Asignatura: | P12: ESTUDIOS SOCIALES
A13: A.P.8 | B13: Utilizar dentro de la propuesta pedagógica actividades que refuercen la autoestima como: expresión de sentimientos, respeto a la diferencia y tolerancia. | M13: Primer Período ( X ) | O13: Segundo Período ( )
A14: A.P.9 | B14: Utilizar reforzadores sociales como: "muy bien", "usted puede" y "siga así". | K14: Descripción del funcionamiento del Estudiante: | S14: ELIJA UN CÓDIGO Y SE DESPLEGA LA INFORMACIÓN
A15: A.P.10 | B15: Utilizar canales sensoriales como: auditivos, kinestésico y táctil para presentar la materia. | K15: Código | M15: Apoyos personales | O15: Resultados
A16: A.P.11 | B16: Generar alguna técnica para recordar frecuentemente la entrega de trabajos a largo plazo. | K16: A.P.4 | M16: =IFERROR(INDEX($B$6:$B$18, MATCH(K16, $A$6:$A$18, 0)), " ") -> Reforzar cada logro por más pequeño que este sea.
A17: A.P.12 | B17: Referir a otros especialistas (orientador, docente de apoyo, psicología, terapia física, terapia de lenguaje, otros).
A18: A.P.13 | B18: Otros: | K18: A.P.3 | M18: =IFERROR(INDEX($B$6:$B$18, MATCH(K18, $A$6:$A$18, 0)), " ") -> Brindar acercamiento físico y las manifestaciones de apoyo.
B19: Apoyos Organizativos Sugeridos
A20: A.A.13 | B20: Ubicar al estudiante cerca de compañeros que no se desconcentren. | K20: A.P.2 | M20: =IFERROR(INDEX($B$6:$B$18, MATCH(K20, $A$6:$A$18, 0)), " ") -> Utilizar la tutoría entre compañeros.
A21: A.A.14 | B21: Ubicar al estudiante donde mejor pueda ver la pizarra.
A22: A.A.15 | B22: Sentar al estudiante en un lugar donde tenga buena iluminación | K22: Código | M22: Apoyos Organizativos (A.A) | O22: Resultados
A23: A.A.16 | B23: Considerar colocar los asientos en semicírculo.
A24: A.A.17 | B24: Rotular objetos y partes importantes de la clase. | K24: A.A.15 | M24: =IFERROR(INDEX($B$20:$B$30, MATCH(K24, $A$20:$A$30, 0)), " ") -> Sentar al estudiante en un lugar donde tenga buena iluminación
A25: A.A.18 | B25: Organizar y agrupar los y las estudiantes de acuerdo con sus intereses motivacionales
A26: A.A.19 | B26: Organizar el tiempo y del espacio para mejorar el clima organizacional. | K26: A.A.19 | M26: =IFERROR(INDEX($B$20:$B$30, MATCH(K26, $A$20:$A$30, 0)), " ") -> Organizar el tiempo y del espacio para mejorar el clima organizacional.
A27: A.A.20 | B27: Anotar la fecha de exámenes y entrega de trabajo en un lugar visible.
A28: A.A.21 | B28: Establecer rutinas de trabajo. | K28: A.A.13 | M28: =IFERROR(INDEX($B$20:$B$30, MATCH(K28, $A$20:$A$30, 0)), " ") -> Ubicar al estudiante cerca de compañeros que no se desconcentren.
A29: A.A.22 | B29: Anotar en la pizarra el número de página y/o ejercicios a realizar.
A30: A.A.23 | B30: Otras: | K30: Código | M30: Apoyos Materiales y Tecnológicos (A.A) | O30: Resultados
B32: Apoyos Materiales y Tecnológicos sugeridos | K32: A.A.29 | M32: =IFERROR(INDEX($B$33:$B$49, MATCH(K32, $A$33:$A$49, 0)), " ") -> Usar láminas, mapas, gráficos y vídeos relacionados con los aprendizajes que se desarrollan.
A33: A.A.23 | B33: Ampliar la letra al tamaño que el estudiante sienta mejor.
A34: A.A.24 | B34: Permitir el uso de lámparas y lupas para que pueda tener una mejor visión. | K34: A.A.36 | M34: =IFERROR(INDEX($B$33:$B$49, MATCH(K34, $A$33:$A$49, 0)), " ") -> Facilitar material de reforzamiento para hacer en casa.
A35: A.A.25 | B35: Utilización de rotafolios escribiendo con marcador grueso y letra amplia como material de apoyo de temas vistos en clase.
A36: A.A.26 | B36: Permitir el uso de dispositivos para que realice grabaciones en clases. | K36: A.A.23 | M36: =IFERROR(INDEX($B$33:$B$49, MATCH(K36, $A$33:$A$49, 0)), " ") -> Ampliar la letra al tamaño que el estudiante sienta mejor.
A37: A.A.27 | B37: Usar marcadores gruesos preferiblemente azul o negro para escribir en la pizarra.
A38: A.A.28 | B38: Permitir el uso del diccionario para ejecución de trabajo cotidiano y pruebas.
A39: A.A.29 | B39: Usar láminas, mapas, gráficos y vídeos relacionados con los aprendizajes que se desarrollan.
A40: A.A.30 | B40: Permitir el uso de las tablas de multiplicar para ejecución de trabajo cotidiano y pruebas.
A41: A.A.31 | B41: Permitir el uso de la calculadora para la ejecución de trabajo cotidiano y pruebas. | K41: Código | M41: Apoyos Curriculares (Metodología)(A.C.) | O41: Resultados
A42: A.A.32 | B42: Permitir el uso de fichas con las fórmulas matemáticas para ejecución de trabajo cotidiano y pruebas.
...

Sheet MATEMATICA
N1: ÁREA DE TRABAJO PARA EL INFORME
B3: GUÍA DE LOS CÓDIGOS
U4: =IFERROR(INDEX('LISTA DE ESTUDIANTES'!$C$2:$C$102, MATCH($N$10,'LISTA DE ESTUDIANTES'!B2:B102, 0)), " ") -> 8-1
B5: Apoyos sugeridos que podría brindar el docente regular. | C5: VIDEO DE USO:
A6: A.P.1 | B6: Utilizar su cercanía física para mantenerlo atento a la clase. | S6: CTRL + P, PARA IMPRIMIR O TAMBIÉN LO PUEDE GUARDAR COMO PDF
A7: A.P.2 | B7: Utilizar la tutoría entre compañeros. | M7: ANEXO 2: REGISTRO DE APOYOS EDUCATIVOS
A8: A.P.3 | B8: Brindar acercamiento físico y las manifestaciones de apoyo. | N8: Curso lectivo 2025
A9: A.P.4 | B9: Reforzar cada logro por más pequeño que este sea. | C9: https://youtu.be/wF6TR_aaiRc | K9: Institución: Colegio Nocturno La Cuesta | P9: Circuito: 06
A10: A.P.5 | B10: Reforzar la autoestima mediante actividades que le permitan éxito, particularizando en características cognitivas y sociales. | K10: Nombre del estudiante: | N10: =+'ESPAÑOL '!N10 -> Caballero González Angie Guiselle | P10: =+ "Sección: " &$U$4 -> Sección: 8-1 | S10: ESCOJA UN ESTUDIANTE EN LA LISTA Y SE DEPLEGA TODA LA INFORMACIÓN RELACIONADA
A11: A.P.6 | B11: Utilizar constantemente la estrategia de trabajo cooperativo con la finalidad de que logre beneficiar y beneficiarse de las experiencias de otros compañeros y así reforzar su seguridad en la ejecución de los aprendizajes. | K11: Nivel de Funcionamiento: | N11: =IFERROR(INDEX('LISTA DE ESTUDIANTES'!$E$2:$E$102,MATCH($N$10,'LISTA DE ESTUDIANTES'!$B$2:$B$102, 0)), " ") -> Revisar Expediente | P11: =+TODAY() -> 46158
A12: A.P.7 | B12: Dar responsabilidades especificas al estudiante dentro del aula y hogar para reforzar su autoconfianza generando responsabilidad e independencia. | K12: Docente responsable: | N12: Gerardo Ramirez Rojas | O12: Asignatura: | P12: ESTUDIOS SOCIALES
A13: A.P.8 | B13: Utilizar dentro de la propuesta pedagógica actividades que refuercen la autoestima como: expresión de sentimientos, respeto a la diferencia y tolerancia. | M13: Primer Período ( X ) | O13: Segundo Período ( )
A14: A.P.9 | B14: Utilizar reforzadores sociales como: "muy bien", "usted puede" y "siga así". | K14: Descripción del funcionamiento del Estudiante: | S14: ELIJA UN CÓDIGO Y SE DESPLEGA LA INFORMACIÓN
A15: A.P.10 | B15: Utilizar canales sensoriales como: auditivos, kinestésico y táctil para presentar la materia. | K15: Código | M15: Apoyos personales | O15: Resultados
A16: A.P.11 | B16: Generar alguna técnica para recordar frecuentemente la entrega de trabajos a largo plazo. | K16: A.P.4 | M16: =IFERROR(INDEX($B$6:$B$18, MATCH(K16, $A$6:$A$18, 0)), " ") -> Reforzar cada logro por más pequeño que este sea.
A17: A.P.12 | B17: Referir a otros especialistas (orientador, docente de apoyo, psicología, terapia física, terapia de lenguaje, otros).
A18: A.P.13 | B18: Otros: | K18: A.P.3 | M18: =IFERROR(INDEX($B$6:$B$18, MATCH(K18, $A$6:$A$18, 0)), " ") -> Brindar acercamiento físico y las manifestaciones de apoyo.
B19: Apoyos Organizativos Sugeridos
A20: A.A.13 | B20: Ubicar al estudiante cerca de compañeros que no se desconcentren. | K20: A.P.2 | M20: =IFERROR(INDEX($B$6:$B$18, MATCH(K20, $A$6:$A$18, 0)), " ") -> Utilizar la tutoría entre compañeros.
A21: A.A.14 | B21: Ubicar al estudiante donde mejor pueda ver la pizarra.
A22: A.A.15 | B22: Sentar al estudiante en un lugar donde tenga buena iluminación | K22: Código | M22: Apoyos Organizativos (A.A) | O22: Resultados
A23: A.A.16 | B23: Considerar colocar los asientos en semicírculo.
A24: A.A.17 | B24: Rotular objetos y partes importantes de la clase. | K24: A.A.15 | M24: =IFERROR(INDEX($B$20:$B$30, MATCH(K24, $A$20:$A$30, 0)), " ") -> Sentar al estudiante en un lugar donde tenga buena iluminación
A25: A.A.18 | B25: Organizar y agrupar los y las estudiantes de acuerdo con sus intereses motivacionales
A26: A.A.19 | B26: Organizar el tiempo y del espacio para mejorar el clima organizacional. | K26: A.A.19 | M26: =IFERROR(INDEX($B$20:$B$30, MATCH(K26, $A$20:$A$30, 0)), " ") -> Organizar el tiempo y del espacio para mejorar el clima organizacional.
A27: A.A.20 | B27: Anotar la fecha de exámenes y entrega de trabajo en un lugar visible.
A28: A.A.21 | B28: Establecer rutinas de trabajo. | K28: A.A.13 | M28: =IFERROR(INDEX($B$20:$B$30, MATCH(K28, $A$20:$A$30, 0)), " ") -> Ubicar al estudiante cerca de compañeros que no se desconcentren.
A29: A.A.22 | B29: Anotar en la pizarra el número de página y/o ejercicios a realizar.
A30: A.A.23 | B30: Otras: | K30: Código | M30: Apoyos Materiales y Tecnológicos (A.A) | O30: Resultados
B32: Apoyos Materiales y Tecnológicos sugeridos | K32: A.A.29 | M32: =IFERROR(INDEX($B$33:$B$49, MATCH(K32, $A$33:$A$49, 0)), " ") -> Usar láminas, mapas, gráficos y vídeos relacionados con los aprendizajes que se desarrollan.
A33: A.A.23 | B33: Ampliar la letra al tamaño que el estudiante sienta mejor.
A34: A.A.24 | B34: Permitir el uso de lámparas y lupas para que pueda tener una mejor visión. | K34: A.A.36 | M34: =IFERROR(INDEX($B$33:$B$49, MATCH(K34, $A$33:$A$49, 0)), " ") -> Facilitar material de reforzamiento para hacer en casa.
A35: A.A.25 | B35: Utilización de rotafolios escribiendo con marcador grueso y letra amplia como material de apoyo de temas vistos en clase.
A36: A.A.26 | B36: Permitir el uso de dispositivos para que realice grabaciones en clases. | K36: A.A.23 | M36: =IFERROR(INDEX($B$33:$B$49, MATCH(K36, $A$33:$A$49, 0)), " ") -> Ampliar la letra al tamaño que el estudiante sienta mejor.
A37: A.A.27 | B37: Usar marcadores gruesos preferiblemente azul o negro para escribir en la pizarra.
A38: A.A.28 | B38: Permitir el uso del diccionario para ejecución de trabajo cotidiano y pruebas.
A39: A.A.29 | B39: Usar láminas, mapas, gráficos y vídeos relacionados con los aprendizajes que se desarrollan.
A40: A.A.30 | B40: Permitir el uso de las tablas de multiplicar para ejecución de trabajo cotidiano y pruebas.
A41: A.A.31 | B41: Permitir el uso de la calculadora para la ejecución de trabajo cotidiano y pruebas. | K41: Código | M41: Apoyos Curriculares (Metodología)(A.C.) | O41: Resultados
A42: A.A.32 | B42: Permitir el uso de fichas con las fórmulas matemáticas para ejecución de trabajo cotidiano y pruebas.
...
