Workbook

Sheet Adecuaciones Significativas
B1: COLEGIO TÉCNICO PROFESIONAL AGROPECUARIO DE SABALITO.
B2: LISTADO DE ADECUACIONES CURRICULARES 2026.
B6: Estudiante | C6: Sección | D6: Cédula | E6: Género | F6: Nivel de funcionamiento | G6: Observaciones
A7: 1 | B7: Arias Barrantes Isaac | C7: 9-4 | D7: 605260493 | E7: masculino | F7: Nivel de funcionamiento Inglés Académico y conversacional 4°, Francés, Matemáticas, Ciencias, Estudios Sociales 6° y Español 7°, | G7: Discapacidad Intelectual
A8: 2 | B8: Bejerano Bejerano Víctor | C8: 8-1 | D8: 605290200 | E8: masculino | F8: Nivel de funcionamiento 2°. | G8: Discapacidad intelectual
A9: 3 | B9: Bejerano Morales Norberth | C9: 7-5 | D9: 305980180 | E9: masculino | F9: Nivel de funcionamiento 3° | G9: Discpacidad intelectual . Repite sétimo. | H9: R
A10: 4 | B10: Cárdenas Fonseca Aarón Josué | C10: 10-3 | D10: 120440498 | E10: masculino | F10: Nivel de funcionamiento: Español 7°, Matematica 6°, Ciencias 5°, Estudios Sociales 7°, Cívica 7°, Inglés 6°, Especialidad 10°. | G10: Discapacidad Intelectual
A11: 5 | B11: Carmona Vásquez Yoene | C11: 7-1 | D11: 605400822 | E11: femenino | F11: Nivel de funcionamiento 3° | G11: Discapacidad Intelectual. Repite Sétimo | H11: R
A12: 6 | B12: Carrera Amador Ilder | C12: 7-1 | D12: 121510987 | E12: masculino | F12: Nivel de funcionamiento 2° I ciclo | G12: Discapacidad intelectual, pérdida auditiva. El padre no acepta que esté en plan nacional, recibe quimioterapia, utiliza audífonos, determinar avance, lectura, escritura.Repite sétimo. | H12: R
A13: 7 | B13: Castro Campos Vielka Dalay | C13: 9-1 | D13: 605330091 | E13: femenino | F13: Nivel de funcionamiento Inglés Académico y conversacional 5°, Francés, Matemáticas, Español Ciencias, y Español 6°,y Estudios Sociales 7° | G13: Discapacidad Intelectual
A14: 8 | B14: Cortés Gómez Lewis David | C14: 11-1 | D14: 605140374 | E14: masculino | F14: Nivel de funcionamiento: Español 8°, Matemática 7°, Quimica 8°, Biología 8°, Estudios Sociales 9°, Cívica 8°, Inglés 7°, Especialidad 10° | G14: Discapacidad Intelectual
A15: 9 | B15: Fernández Salas Justin Said. | C15: 7-1 | D15: 121190969 | E15: masculino | F15: Nivel de funcionamiento 3° grado I ciclo. | G15: Discapacidad intelectual. Determinar avance, lectura y escritura, padres matriculan en aula regular.Repite sétimo | H15: R
A16: 10 | B16: García Fernández Jorge Joshua | C16: 8-3 | D16: 605360677 | E16: masculino | F16: Nivel de funcionamiento 4° II ciclo. | G16: Discapacidad intelectual.
A17: 11 | B17: Hernández Valencia Yeiny | C17: 8-1 | D17: 605390382 | E17: femenino | F17: Nivel de funcionamiento 3° | G17: Hacer observaciones avances y lectoescritura
A18: 12 | B18: Jiménez Jiménez Víctor | C18: 9-4 | D18: 605350923 | E18: masculino | F18: Nivel de funcionamiento Inglés Académico y conversacional 4°, Matemáticas 5°, Español, Ciencias, Estudios Sociales y Françés 6°. | G18: Discapacidad Intelectual
A19: 13 | B19: Martínez Jiménez Kimberly Alexandra | C19: 9-6 | D19: 605230219 | E19: femenino | F19: Nivel de funcionamiento 4° | G19: Discapacidad Intelectual
A20: 14 | B20: Miranda Ábrego Amelia | C20: 8-6 | D20: 605260597 | E20: femenino | F20: Nivel de funcionamiento 3° grado I ciclo | G20: Discapacidad intelectual. Determinar avance, lectura y escritura, padres matriculan en aula regular.
A21: 15 | B21: Molina Molina Fernando | C21: 10-3 | D21: 605210177 | E21: masculino | F21: Nivel de funcionamiento: Español 9°, Matemática 7°,Física 8°, Estudios Sociales 9°, Cívica 9°, Inglés 8°, Especialidad 10° | G21: Discapacidad Intelectual. Repite décimo
A22: 16 | B22: Morales Palacios Samuel | C22: 8-1 | D22: 124010122 | E22: masculino | F22: Nivel de funcionamiento 2° escuela | G22: Discapacidad intelectual
A23: 17 | B23: Picado Pérez Evelyn Susana | C23: 11-2 | D23: 305850706 | E23: femenino | F23: Nivel de Funcionamiento: Español 9°, Matemática 7°, Química 7°, Biología 7°, Estudios Sociales 9°, Cívica 8°, Inglés 7°, Especialidad 10°. | G23: Discapacidad Intelectual
A24: 18 | B24: Portugués Villegas Ingrid | C24: 11-2 | D24: 605140899 | E24: femenino | F24: Nivel de Funcionamiento: Español 9°, Matemática 7°, Química 7°, Biología 7°, Estudios Sociales 9°, Cívica 8°, Inglés 7°, Especialidad 10°. | G24: Discapacidad Intelectual
A25: 19 | B25: Salas Fernández Ashly Valeria | C25: 7-6 | D25: 6-0542-0643 | E25: femenino | F25: Nivel de funcionamiento 3° grado primaria. | G25: Discapacidad Intelectual
A26: 20 | B26: Sandoya Mendoza Maricel | C26: 7-7 | D26: 1591011446616 | E26: femenino | F26: Nivel de funcionamiento 3° | G26: Discpacidad intelectual en TODAS las asignaturas. Repite sétimo. | H26: R
A27: 21 | B27: Valverde González Eimy Yaslin | C27: 8-5 | D27: 605360674 | E27: femenino | F27: Nivel de funcionamiento 3 | G27: traslado a Coto Brus encargada PANI. Discapacidad Intelectual
A28: 22 | B28: Villegas Acuña Hilary Michel | C28: 12-4 | D28: 604980512 | E28: femenino | F28: Nivel de funcionamiento: Español 9°, Matemáticas,Química, Biología, Estudios Sociales, Cívica, Física, Elementos de Gestión y Agronegocios 10°. | G28: Discapacidad Intelectual
A29: 23 | B29: Abrego Morales Migdalia | C29: 7-1 | E29: femenino | F29: Nivel de funcionamiento 2° grado primaria | G29: Discapacidad intelectual
A30: 24 | B30: García Figueroa Kinberlin | C30: 7-6 | E30: femenino | F30: Nivel de funcionamiento 2° grado primaria | G30: Discapacidad intelectual y epilepsia
A31: 25 | B31: Guevara González Jose Alfredo | C31: 7-3 | E31: masculino | F31: Nivel de funcionamiento 2° grado primaria | G31: DI
A32: 26 | B32: Jiménez Castro Emily Anyelina | C32: 7-1 | E32: femenino | F32: Nivel de funcionamiento 3° grado primaria
A33: 27 | B33: Jiménez Jiménez Mario | C33: 7-1 | E33: masculino | F33: Nivel de funcionamiento 2° grado primaria | G33: DI
A34: 28 | B34: Jimenez Zúñiga Nataly Valeria | C34: 7-7 | E34: femenino | F34: No esta expediente en colegio datos obtenidos plataforma SABER | G34: DI
A35: 29 | B35: Martinez Montenegro Esthefany | C35: 7-5 | E35: femenino | F35: No esta expediente en colegio datos obtenidos plataforma SABER | G35: DI + asma
A36: 30 | B36: Montezuma Bejarano Karola | C36: 7-2 | E36: femenino | F36: No esta expediente en colegio datos obtenidos plataforma SABER | G36: DI + Epilepsia
A37: 31 | B37: Morales Baker Saul | C37: 7-5 | E37: masculino | F37: Nivel de funcionamiento 3° grado I ciclo | G37: DI
A38: 32 | B38: Navarro Pérez Anderson Miguel | C38: 7-1 | E38: masculino | F38: Nivel de funcionamiento 2° grado primaria | G38: DI
A39: 33 | B39: Palacios Quintero María Valeria | C39: 7-6 | E39: femenino | F39: Nivel de funcionamiento 1° grado primaria | G39: DI
A40: 34 | B40: Quintero Sandoya Joel Yarot | C40: 7-1 | E40: masculino | F40: Nivel de funcionamiento 1° grado primaria | G40: DI
A41: 35 | B41: Sandi Marín Eduard Alonso | C41: 7-2 | E41: masculino | F41: Nivel de funcionamiemto 2° grado primaria | G41: DI
A42: 36 | B42: Ugalde Hernández Karen Susana | C42: 8-1 | E42: femenino | F42: Nivel de funcionamiemto 3° grado primaria | G42: DI (2025 en Plan Nacional CTPUM)
A43: 37 | B43: Jiménez Zúñiga Nataly Valeria | C43: 7-7 | D43: 121450578 | E43: femenino | F43: Nivel de funcionamiento 3° grado primaria | G43: Discapacidad Intelectual
...

Sheet Adecuaciones no significativas
B1: COLEGIO TÉCNICO PROFESIONAL AGROPECUARIO DE SABALITO.
B2: LISTADO DE ADECUACIONES CURRICULARES 2026.
B6: Estudiante | C6: Sección | D6: Cédula | E6: Repite | F6: Observaciones
A7: 1 | B7: =UPPER(Hoja1!A2&" "&Hoja1!B2&" "&Hoja1!C2) -> ABREGO . WALTER | C7: 7-1 | F7: PA
A8: 2 | B8: =UPPER(Hoja1!A3&" "&Hoja1!B3&" "&Hoja1!C3) -> ABREGO MIRANDA HERIBERTO JORGE | C8: 7-4 | F8: PA
A9: 3 | B9: Alemán Sandí Jimena | C9: 9-1 | D9: 605320280 | F9: P.A
A10: 4 | B10: =UPPER(Hoja1!A4&" "&Hoja1!B4&" "&Hoja1!C4) -> ALEMAN SANDI JONATHAN | C10: 7-2 | F10: PA
A11: 5 | B11: Alvarado Guzmán Samantha | C11: 8-5 | D11: 121620521 | F11: P.A.
A12: 6 | B12: Arias Porras Britanny | C12: 11-4 | D12: 120470353 | F12: PA
A13: 7 | B13: Arias Vindas Hazel Lineth | C13: 9-6 | D13: 120910578 | F13: P.A
A14: 8 | B14: Artavia Ugarte Jhoan José | C14: 8-4 | D14: 121540833 | F14: Déficit Atencional, dificultad lectora-comprensiva-analítica.
A15: 9 | B15: =UPPER(Hoja1!A5&" "&Hoja1!B5&" "&Hoja1!C5) -> AVILES JIMENEZ THAIRYN JOSEBETH | C15: 7-6 | F15: PA
A16: 10 | B16: Avilés Jiménez Yareth Alejandra | C16: 9-2 | D16: 120870488 | F16: P.A
A17: 11 | B17: Barrantes Vargas Luis Felipe | C17: 9-3 | D17: 605310238 | F17: P.A
A18: 12 | B18: Beita Vargas Rony | C18: 8-4 | D18: 121270094 | F18: P.A
A19: 13 | B19: Bejerano--------- Viviana | C19: 8-3 | D19: 15910111
A20: 14 | B20: Blanco Cubero Aaron Fabricio | C20: 8-4 | D20: 605410373 | F20: Dificultad procesos de atención y percepción, Dificultad para iniciar y finalizar una actividad. TEA
A21: 15 | B21: Blanco García Roxiri Paola | C21: 8-3 | D21: 605410463 | F21: PA
A22: 16 | B22: Bonilla Fallas Valentina | C22: 8-5 | D22: 605410700 | F22: Baja visión
A23: 17 | B23: Cascante Vargas Víctor Manuel | C23: 8-4 | D23: 605290162 | E23: X | F23: P.A
A24: 18 | B24: =UPPER(Hoja1!A6&" "&Hoja1!B6&" "&Hoja1!C6) -> CHAVES ALVAREZ DARLENE ARELIZ | C24: 7-5 | F24: PA
A25: 19 | B25: =UPPER(Hoja1!A7&" "&Hoja1!B7&" "&Hoja1!C7) -> CHAVES SALAZAR MAIDELYN ANDREINA | C25: 8-1 | F25: PA
A26: 20 | B26: Chaves Valerio Alisson Pamela | C26: 7-1 | D26: 121600888 | E26: X | F26: PA
A27: 21 | B27: Chaves Valerio Royer David | C27: 9-4 | D27: 121070344 | F27: P.A
A28: 22 | B28: Cherlin Yarixa Picado Muñoz | C28: 8-1 | D28: 605390846 | F28: PA
A29: 23 | B29: Cruz González Lisandro | C29: 9-2 | D29: 605350919 | F29: P.A
A30: 24 | B30: =UPPER(Hoja1!A8&" "&Hoja1!B8&" "&Hoja1!C8) -> DURAN VARGAS KEYLIN | C30: 7-1 | F30: PA
A31: 25 | B31: Erikca Yariela Elizondo Soto | C31: 8-2 | D31: 605380655 | F31: PA.
A32: 26 | B32: Espinoza Villalobos Eidan Santiago | C32: 8-4 | D32: 605360225 | F32: PA
A33: 27 | B33: Flores Prado Lana Jazlin | C33: 9-4 | D33: 121370062 | F33: P.A
A34: 28 | B34: Fonseca Blanco Sharon Jenasha | C34: 12-1 | D34: 119850637 | F34: PA
A35: 29 | B35: =UPPER(Hoja1!A9&" "&Hoja1!B9&" "&Hoja1!C9) -> FONSECA CONCEPCION ANGELO DAVID | C35: 7-5 | F35: PA
A36: 30 | B36: García Miranda Marta | C36: 7-7 | D36: 605380595 | E36: X | F36: P.A.
A37: 31 | B37: Gómez Granados Angely Lucía | C37: 10-5 | D37: 120960941 | F37: P.A Tiempo extra en los trabajos.
A38: 32 | B38: González Abarca Justin Estarlen | C38: 8-2 | D38: 605280177 | F38: PA (PROBLEMAS DE APRENIZAJE)
A39: 33 | B39: =UPPER(Hoja1!A10&" "&Hoja1!B10&" "&Hoja1!C10) -> GONZÁLEZ ZAPATA OBETH MARTÍN | C39: 7-1 | F39: PA
A40: 34 | B40: =UPPER(Hoja1!A11&" "&Hoja1!B11&" "&Hoja1!C11) -> GUERRA CASTILLO AGUSTIN | C40: 7-6 | F40: PA
A41: 35 | B41: =UPPER(Hoja1!A12&" "&Hoja1!B12&" "&Hoja1!C12) -> GUTIERREZ DUARTE ANGELO EFREN | C41: 7-7 | F41: PA
A42: 36 | B42: Guzmán Muñoz Alana | C42: 9-3 | D42: 121030133 | F42: Déficit Atencional, dislexia, discalculia
A43: 37 | B43: Isabella Francini Navas Mena | C43: 8-1 | D43: 121470877 | F43: PA
...

Sheet Hoja1
A1: Primer apellido | B1: Segundo apellido | C1: Nombre
A2: ABREGO | B2: . | C2: WALTER
A3: ABREGO | B3: MIRANDA | C3: HERIBERTO JORGE
A4: ALEMAN | B4: SANDI | C4: JONATHAN
A5: AVILES | B5: JIMENEZ | C5: THAIRYN JOSEBETH
A6: CHAVES | B6: ALVAREZ | C6: DARLENE ARELIZ
A7: CHAVES | B7: SALAZAR | C7: MAIDELYN ANDREINA
A8: DURAN | B8: VARGAS | C8: KEYLIN
A9: FONSECA | B9: CONCEPCION | C9: ANGELO DAVID
A10: GONZÁLEZ | B10: ZAPATA | C10: OBETH MARTÍN
A11: GUERRA | B11: CASTILLO | C11: AGUSTIN
A12: GUTIERREZ | B12: DUARTE | C12: ANGELO EFREN
... A38: ZUÑIGA | B38: BUZANO | C38: ELIAZAR ISMAEL

Sheet Adecuaciones de Acceso
B1: COLEGIO TÉCNICO PROFESIONAL AGROPECUARIO DE SABALITO.
B2: LISTADO DE ADECUACIONES CURRICULARES 2025.
B6: Estudiante | C6: Sección | D6: Cédula | E6: Observaciones
A7: 1 | B7: Cordero Mora Arlen Dariana | C7: 9-1 | D7: 605280086 | E7: Hipotiroidismo. Astigmatismo. Asma. Alopecia areata. Dermatitis atópica. Rinitis crónica.Trastorno de ansiedad. Antecedente pie bot. Tratamiento crónico. Puede realizar educación física, pero con adaptación a sus necesidades. Madre de familia Emilia Mora Sánchez WhatsApp 83909679.
A8: 2
A9: 3
A10: 4
A11: 5
A12: 6
A13: 7
A14: 8
A15: 9
A16: 10
A17: 11
A18: 12
A19: 13

Sheet Traslados
B1: Estudiante | C1: Sección | D1: Cédula | E1: Nivel de funcionamiento | F1: Observaciones
A2: 2 | B2: Arias Fernández Josué se trasladó | C2: 8-6 | D2: 605230224 | E2: Niveles de funcionamiento: Inglés e inglés conversacional 5°, Español, Matemáticas, Ciencias y Francés 6°, y Estudios Sociales 7°. | F2: Discapacidad Intelectual
A3: 3 | B3: Avilés Vega Abigail Se trasladó | C3: 10-1 | D3: 605180511 | E3: Nivel Funcionamiento: Expediente no esta en la institución | F3: Discapacidad Intelectual
A4: 6 | B4: Blanco López Leonardo Gabriel Se trasladó | C4: 9-6 | D4: 120590168 | E4: Nivel de funcionamiento: Inglés conversacional 6°,Ciencias, Matemáticas, Inglés 7°, Francés, Español, y Estudios Sociales 7° . | F4: Discapacidad Intelectual
A5: 10 | B5: Castillo Jiménez Dana Sofia Se trasladó | C5: 10-2 | D5: 605240675 | E5: Nivel de Funcionamiento: Ciencias e inglés 6°, Matemáticas, inglés 7°, Francés y Cívica 8°, Matemáticas 7°, Español 9. | F5: Discapacidad Intelectual
A6: 12 | B6: Córtes Gómez Eiden Matias se trasladó | C6: 8-6 | D6: 605390380 | E6: Nivel de funcionamiento Inglés Académico y conversacional 5°, Matemáticas, Ciencias, Estudios Sociales y Francés 6°, Español 7°. | F6: Discapacidad Intelectual
A7: 15 | B7: Flores Blanco Deiner Duvan Desertó | C7: 7-3 | D7: 605300175 | E7: Niveles de funcionamiento: español 6°, matemática 5°, ciencias 6°, estudios sociales 6°, inglés académico 5°, inglés conversacional 5°, francés 6° | F7: Dispacidad Intelectual
A8: 17 | B8: Hernádez Fernández Randy A. Se trasladó | C8: 8-1 | D8: 605240015 | E8: Nivel de funcionamiento Inglés Académico y conversacional 4°, Francés, Matemáticas, Ciencias, Estudios Sociales 6° y Español 7°, | F8: Discapacidad Intelectual
A9: 19 | B9: Hernández Valencia Yendry Nicole se trasladó | C9: 8-5 | D9: 605230862 | E9: Nivel de funcionamiento 3° | F9: Discapacidad Intelectual
A10: 21 | B10: Lorenzano Moraga Escaleth Viviana Desertó 2025 | C10: 8-1 | D10: 605290484 | E10: Nivel de funcionamiento 7° | F10: Discapacidad Intelectual
A11: 25 | B11: Monge Cruz Beyllanit Darine se trasladó | C11: 7-6 | D11: 121360350 | E11: Nivel de funcionamiento 3° | F11: Déficit atencional, epilepsia, medicada
A12: 26 | B12: Montoya Araúz Engel Samuel Plan Nacional | C12: 8° | D12: 605400254 | E12: Nivel de funcionamiento 1° | F12: Hacer observaciones avances y lectoescritura.
A13: 28 | B13: Palacios Ábregos Jorge Se trasladó | C13: 9-4 | D13: YR2023-06263 | E13: Nivel de funcionamiento: Español 5°, Matemáticas 6° y Ciencias, Inglés, Estudios Sociales 7°. | F13: Discapacidad Intelectual
A14: 30 | B14: Pinzon Moreno Alberto Traslado | C14: 7-7 | D14: 605210622 | E14: Nivel de funcionamiento:Inglés y Matemáticas 5°, Estudios Sociales, Francés, y Ciencias 6°, Cívica 7° | F14: Discapacidad intelectual.
A15: 35 | B15: Vilchez Zúñiga Sebastían Alonso Se trasladó | C15: 7-3 | D15: 121000627 | E15: Nivel de funcionamiento 2° I ciclo
